Workbook

Sheet Gesamtauswertung
A1: Nummer | B1: Dienstgrad | C1: Name | D1: Anzahl der teilgenommenen Gefechte | E1: Beförderungsschwelle erreicht?
A2: 1 | B2: =Dateneingabe!#REF! -> #REF! | C2: =Dateneingabe!#REF! -> #REF! | D2: =Dateneingabe!#REF! -> #REF! | E2: =Dateneingabe!#REF! -> #REF! | J2: Schnellinformation bzgl Vorgabenstatus der Unteroffiziere
A3: 2 | B3: =Dateneingabe!#REF! -> #REF! | C3: =Dateneingabe!#REF! -> #REF! | D3: =Dateneingabe!#REF! -> #REF! | E3: =Dateneingabe!#REF! -> #REF! | J3: Kamerad erfüllt Dienstzeit + Gefechte
A4: 3 | B4: =Dateneingabe!#REF! -> #REF! | C4: =Dateneingabe!#REF! -> #REF! | D4: =Dateneingabe!#REF! -> #REF! | E4: =Dateneingabe!#REF! -> #REF! | J4: GT/CW als Kommander geführt
A5: 4 | B5: =Dateneingabe!#REF! -> #REF! | C5: =Dateneingabe!#REF! -> #REF! | D5: =Dateneingabe!#REF! -> #REF! | E5: =Dateneingabe!#REF! -> #REF! | J5: GT/CW als Truppführer geführt
A6: 5 | B6: =Dateneingabe!#REF! -> #REF! | C6: =Dateneingabe!#REF! -> #REF! | D6: =Dateneingabe!#REF! -> #REF! | E6: =Dateneingabe!#REF! -> #REF!
A7: 6 | B7: =Dateneingabe!#REF! -> #REF! | C7: =Dateneingabe!#REF! -> #REF! | D7: =Dateneingabe!#REF! -> #REF! | E7: =Dateneingabe!#REF! -> #REF!
A8: 7 | B8: =Dateneingabe!#REF! -> #REF! | C8: =Dateneingabe!#REF! -> #REF! | D8: =Dateneingabe!#REF! -> #REF! | E8: =Dateneingabe!#REF! -> #REF!
A9: 8 | B9: =Dateneingabe!#REF! -> #REF! | C9: =Dateneingabe!#REF! -> #REF! | D9: =Dateneingabe!#REF! -> #REF! | E9: =Dateneingabe!#REF! -> #REF!
A10: 9 | B10: =Dateneingabe!#REF! -> #REF! | C10: =Dateneingabe!#REF! -> #REF! | D10: =Dateneingabe!#REF! -> #REF! | E10: =Dateneingabe!#REF! -> #REF!
A11: 10 | B11: =Dateneingabe!#REF! -> #REF! | C11: =Dateneingabe!#REF! -> #REF! | D11: =Dateneingabe!#REF! -> #REF! | E11: =Dateneingabe!#REF! -> #REF!
A12: 11 | B12: =Dateneingabe!#REF! -> #REF! | C12: =Dateneingabe!#REF! -> #REF! | D12: =Dateneingabe!#REF! -> #REF! | E12: =Dateneingabe!#REF! -> #REF!
A13: 12 | B13: =Dateneingabe!#REF! -> #REF! | C13: =Dateneingabe!#REF! -> #REF! | D13: =Dateneingabe!#REF! -> #REF! | E13: =Dateneingabe!#REF! -> #REF!
A14: 13 | B14: =Dateneingabe!#REF! -> #REF! | C14: =Dateneingabe!#REF! -> #REF! | D14: =Dateneingabe!#REF! -> #REF! | E14: =Dateneingabe!#REF! -> #REF!
A15: 14 | B15: =Dateneingabe!#REF! -> #REF! | C15: =Dateneingabe!#REF! -> #REF! | D15: =Dateneingabe!#REF! -> #REF! | E15: =Dateneingabe!#REF! -> #REF!
A16: 15 | B16: =Dateneingabe!#REF! -> #REF! | C16: =Dateneingabe!#REF! -> #REF! | D16: =Dateneingabe!#REF! -> #REF! | E16: =Dateneingabe!#REF! -> #REF!
A17: 16 | B17: =Dateneingabe!#REF! -> #REF! | C17: =Dateneingabe!#REF! -> #REF! | D17: =Dateneingabe!#REF! -> #REF! | E17: =Dateneingabe!#REF! -> #REF!
... A57: 56 | B57: =Dateneingabe!#REF! -> #REF! | C57: =Dateneingabe!#REF! -> #REF! | D57: =Dateneingabe!#REF! -> #REF! | E57: =Dateneingabe!#REF! -> #REF!
A58: 57 | B58: =Dateneingabe!B3 -> Anwerber | C58: =Dateneingabe!C3 -> Nachtauge | D58: =Dateneingabe!H3 -> 11 | E58: =Dateneingabe!G3
A59: 58 | B59: =Dateneingabe!B4 -> Anwerber | C59: =Dateneingabe!C4 -> Zylo | D59: =Dateneingabe!H4 -> 2 | E59: =Dateneingabe!G4
A60: 59 | B60: =Dateneingabe!#REF! -> #REF! | C60: =Dateneingabe!#REF! -> #REF! | D60: =Dateneingabe!#REF! -> #REF! | E60: =Dateneingabe!#REF! -> #REF!
A61: 60 | B61: =Dateneingabe!#REF! -> #REF! | C61: =Dateneingabe!#REF! -> #REF! | D61: =Dateneingabe!#REF! -> #REF! | E61: =Dateneingabe!#REF! -> #REF!
A62: 61 | B62: =Dateneingabe!#REF! -> #REF! | C62: =Dateneingabe!#REF! -> #REF! | D62: =Dateneingabe!#REF! -> #REF! | E62: =Dateneingabe!#REF! -> #REF!
A63: 62 | B63: =Dateneingabe!#REF! -> #REF! | C63: =Dateneingabe!#REF! -> #REF! | D63: =Dateneingabe!#REF! -> #REF! | E63: =Dateneingabe!#REF! -> #REF!
A64: 63 | B64: =Dateneingabe!#REF! -> #REF! | C64: =Dateneingabe!#REF! -> #REF! | D64: =Dateneingabe!#REF! -> #REF! | E64: =Dateneingabe!#REF! -> #REF!
A65: 64 | B65: =Dateneingabe!#REF! -> #REF! | C65: =Dateneingabe!#REF! -> #REF! | D65: =Dateneingabe!#REF! -> #REF! | E65: =Dateneingabe!#REF! -> #REF!
A66: 65 | B66: =Dateneingabe!#REF! -> #REF! | C66: =Dateneingabe!#REF! -> #REF! | D66: =Dateneingabe!#REF! -> #REF! | E66: =Dateneingabe!#REF! -> #REF!
A67: 66 | B67: =Dateneingabe!#REF! -> #REF! | C67: =Dateneingabe!#REF! -> #REF! | D67: =Dateneingabe!#REF! -> #REF! | E67: =Dateneingabe!#REF! -> #REF!
A68: 67 | B68: =Dateneingabe!#REF! -> #REF! | C68: =Dateneingabe!#REF! -> #REF! | D68: =Dateneingabe!#REF! -> #REF! | E68: =Dateneingabe!#REF! -> #REF!
A69: 68 | B69: =Dateneingabe!#REF! -> #REF! | C69: =Dateneingabe!#REF! -> #REF! | D69: =Dateneingabe!#REF! -> #REF! | E69: =Dateneingabe!#REF! -> #REF!
A70: 69 | B70: =Dateneingabe!#REF! -> #REF! | C70: =Dateneingabe!#REF! -> #REF! | D70: =Dateneingabe!#REF! -> #REF! | E70: =Dateneingabe!#REF! -> #REF!
A71: 70 | B71: =Dateneingabe!#REF! -> #REF! | C71: =Dateneingabe!#REF! -> #REF! | D71: =Dateneingabe!#REF! -> #REF! | E71: =Dateneingabe!#REF! -> #REF!
... A75: 74 | B75: =Dateneingabe!#REF! -> #REF! | C75: =Dateneingabe!#REF! -> #REF! | D75: =Dateneingabe!#REF! -> #REF! | E75: =Dateneingabe!#REF! -> #REF!
A76: 75 | B76: =Dateneingabe!B5 -> Anwerber | C76: =Dateneingabe!C5 -> Wohin | D76: =Dateneingabe!H5 -> 16 | E76: =Dateneingabe!G5
A77: 76 | B77: =Dateneingabe!B6 -> Anwerber | C77: =Dateneingabe!C6 -> Tornado | D77: =Dateneingabe!H6 -> 19 | E77: =Dateneingabe!G6
A78: 77 | B78: =Dateneingabe!B7 -> Anwerber | C78: =Dateneingabe!C7 -> Mousse | D78: =Dateneingabe!H7 -> 10 | E78: =Dateneingabe!G7
A79: 78 | B79: =Dateneingabe!B8 -> Anwerber | C79: =Dateneingabe!C8 -> Rapmar | D79: =Dateneingabe!H8 -> 15 | E79: =Dateneingabe!G8
A80: 79 | B80: =Dateneingabe!#REF! -> #REF! | C80: =Dateneingabe!#REF! -> #REF! | D80: =Dateneingabe!#REF! -> #REF! | E80: =Dateneingabe!#REF! -> #REF!
A81: 80 | B81: =Dateneingabe!B9 -> Anwerber | C81: =Dateneingabe!C9 -> Patler | D81: =Dateneingabe!H9 -> 7 | E81: =Dateneingabe!G9
A82: 81 | B82: =Dateneingabe!B11 -> Anwerber | C82: =Dateneingabe!C11 -> Lucas | D82: =Dateneingabe!H11 -> 1 | E82: =Dateneingabe!G11
...

Sheet Dateneingabe
L1: 45600 | M1: 45604 | N1: 45605 | O1: 45607 | P1: 45611 | Q1: 45614 | R1: 45618 | S1: 45621 | T1: 45625 | U1: 45626 | V1: 45628 | W1: 45632 | X1: 45633 | Y1: 45635 | Z1: 45639 | AA1: 45640 | AB1: 45641 | AC1: 45642 | AD1: 45646 | AE1: 45649 | AF1: 45653 | AG1: 45656 | AH1: 45660 | AI1: 45663 | AJ1: 45667 | AK1: 45669 | AL1: 45670 | AM1: 45674 | AN1: 45677 | AO1: 45681 | AP1: 45684 | AQ1: 45688 | AR1: 45689 | AS1: 45691 | AT1: 45695 | AU1: 45698 | AV1: 45702 | AW1: 45704 | AX1: 45705 | AY1: 45709 | AZ1: 45712 | BA1: 45716 | BB1: 45719 | BC1: 45723 | BD1: 45725 | BE1: 45726 | BF1: 45730 | BG1: 45733 | BH1: 45737 | BI1: 45738 | BJ1: 45740 | BK1: 45744 | BL1: 45746 | BM1: 45747 | BN1: 45751 | BO1: 45754 | BP1: 45758 | BQ1: 45761 | BR1: 45765 | BS1: 45766 | BT1: 45768 | BU1: 45772 | BV1: 45775 | BW1: 45779 | BX1: 45781 | BY1: 45782 | BZ1: 45786 | CA1: 45787 | CB1: 45789 | CC1: 45793 | CD1: 45795 | CE1: 45796 | CF1: 45797 | CG1: 45800 | CH1: 45801 | CI1: 45802 | CJ1: 45803 | CK1: 45807
A2: Dienstgradstufe | B2: Dienstgrad | C2: Name | D2: Datum Vollmitglied | E2: Datum der letzten Beförderung | F2: Beförderungsschwelle | G2: Schwelle erreicht? | H2: Summe (Seit der letzten Beförderung) | I2: Anwesenheitsquote (Seit der letzten Beförderung) | J2: Summe (gesamt) | K2: Anwesenheitsquote (gesamt) | L2: GT | M2: GT | N2: CW | O2: GT | P2: CW | Q2: GT | R2: GT | S2: GT | T2: GT | U2: CW | V2: GT | W2: GT | X2: CW | Y2: GT | Z2: GT | AA2: CW | AB2: CW | AC2: GT | AD2: GT | AE2: GT | AF2: CW/Event | AG2: GT | AH2: GT | AI2: GT | AJ2: GT | AK2: CW | AL2: GT | AM2: GT | AN2: GT | AO2: GT | AP2: GT | AQ2: GT | AR2: CW | AS2: GT | AT2: GT | AU2: CW | AV2: GT | AW2: CW | AX2: GT | AY2: GT | AZ2: GT | BA2: GT | BB2: GT | BC2: GT | BD2: CW | BE2: GT | BF2: GT | BG2: GT | BH2: GT | BI2: CW | BJ2: GT | BK2: GT | BL2: CW | BM2: GT | BO2: GT | BP2: CW | BQ2: GT | BR2: GT | BS2: Ü CW 7DR | BT2: GT | BU2: Liga 1 | BV2: GT | BW2: GT | BX2: CW | BY2: GT | BZ2: GT | CA2: Liga | CB2: GT | CC2: GT | CD2: CW | CE2: GT | CF2: CW | CG2: GT | CH2: EULiga | CI2: CW | CJ2: GT | CK2: GT
A3: =IFERROR(VLOOKUP(B3,Dienstgradstufen!$A$2:$D$19,3,0),0) -> 1 | B3: Anwerber | C3: Nachtauge | D3: 45693 | E3: 45693 | F3: =IFERROR(VLOOKUP(B3,Dienstgradstufen!$A$2:$D$19,4,0),0) -> 0 | G3: =IF(AND(Dateneingabe!F3>0,Dateneingabe!F3<=Dateneingabe!H3),"Ja","") | H3: {=SUMPRODUCT(L3:DP3,($L$1:$DP$1-E3>=0)*1)} -> 11 | I3: {=IFERROR(H3/SUM(($L$1:$DP$1-E3>=0)*1),0)} -> 0.25 | J3: =SUM(L3:DP3) -> 11 | K3: {=IFERROR(J3/SUM(($L$1:$DP$1-D3>=0)*1),0)} -> 0.25 | AV3: 1 | AW3: 1 | AX3: 1 | AY3: 1 | BA3: 1 | BB3: 1 | BC3: 1 | BD3: 1 | BH3: 1 | BI3: 1 | BK3: 1
A4: =IFERROR(VLOOKUP(B4,Dienstgradstufen!$A$2:$D$19,3,0),0) -> 1 | B4: Anwerber | C4: Zylo | D4: 45695 | E4: 45695 | F4: =IFERROR(VLOOKUP(B4,Dienstgradstufen!$A$2:$D$19,4,0),0) -> 0 | G4: =IF(AND(Dateneingabe!F4>0,Dateneingabe!F4<=Dateneingabe!H4),"Ja","") | H4: {=SUMPRODUCT(L4:DP4,($L$1:$DP$1-E4>=0)*1)} -> 2 | I4: {=IFERROR(H4/SUM(($L$1:$DP$1-E4>=0)*1),0)} -> 0.045454545 | J4: =SUM(L4:DP4) -> 2 | K4: {=IFERROR(J4/SUM(($L$1:$DP$1-D4>=0)*1),0)} -> 0.045454545 | AX4: 1 | AZ4: 1
A5: =IFERROR(VLOOKUP(B5,Dienstgradstufen!$A$2:$D$19,3,0),0) -> 1 | B5: Anwerber | C5: Wohin | D5: 45717 | E5: 45717 | F5: =IFERROR(VLOOKUP(B5,Dienstgradstufen!$A$2:$D$19,4,0),0) -> 0 | G5: =IF(AND(Dateneingabe!F5>0,Dateneingabe!F5<=Dateneingabe!H5),"Ja","") | H5: {=SUMPRODUCT(L5:DP5,($L$1:$DP$1-E5>=0)*1)} -> 16 | I5: {=IFERROR(H5/SUM(($L$1:$DP$1-E5>=0)*1),0)} -> 0.44444444 | J5: =SUM(L5:DP5) -> 16 | K5: {=IFERROR(J5/SUM(($L$1:$DP$1-D5>=0)*1),0)} -> 0.44444444 | BB5: 1 | BD5: 1 | BE5: 1 | BG5: 1 | BI5: 1 | BJ5: 1 | BM5: 1 | BO5: 1 | BQ5: 1 | BT5: 1 | BV5: 1 | BY5: 1 | CA5: 1 | CF5: 1 | CI5: 1 | CJ5: 1
A6: =IFERROR(VLOOKUP(B6,Dienstgradstufen!$A$2:$D$19,3,0),0) -> 1 | B6: Anwerber | C6: Tornado | D6: 45718 | E6: 45718 | F6: =IFERROR(VLOOKUP(B6,Dienstgradstufen!$A$2:$D$19,4,0),0) -> 0 | G6: =IF(AND(Dateneingabe!F6>0,Dateneingabe!F6<=Dateneingabe!H6),"Ja","") | H6: {=SUMPRODUCT(L6:DP6,($L$1:$DP$1-E6>=0)*1)} -> 19 | I6: {=IFERROR(H6/SUM(($L$1:$DP$1-E6>=0)*1),0)} -> 0.52777778 | J6: =SUM(L6:DP6) -> 19 | K6: {=IFERROR(J6/SUM(($L$1:$DP$1-D6>=0)*1),0)} -> 0.52777778 | BC6: 1 | BF6: 1 | BI6: 1 | BM6: 1 | BN6: 1 | BO6: 1 | BR6: 1 | BS6: 1 | BT6: 1 | BW6: 1 | BX6: 1 | BY6: 1 | BZ6: 1 | CA6: 1 | CG6: 1 | CH6: 1 | CI6: 1 | CJ6: 1 | CK6: 1
A7: =IFERROR(VLOOKUP(B7,Dienstgradstufen!$A$2:$D$19,3,0),0) -> 1 | B7: Anwerber | C7: Mousse | D7: 45718 | E7: 45718 | F7: =IFERROR(VLOOKUP(B7,Dienstgradstufen!$A$2:$D$19,4,0),0) -> 0 | G7: =IF(AND(Dateneingabe!F7>0,Dateneingabe!F7<=Dateneingabe!H7),"Ja","") | H7: {=SUMPRODUCT(L7:DP7,($L$1:$DP$1-E7>=0)*1)} -> 10 | I7: {=IFERROR(H7/SUM(($L$1:$DP$1-E7>=0)*1),0)} -> 0.27777778 | J7: =SUM(L7:DP7) -> 10 | K7: {=IFERROR(J7/SUM(($L$1:$DP$1-D7>=0)*1),0)} -> 0.27777778 | BC7: 1 | BD7: 1 | BG7: 1 | BH7: 1 | BI7: 1 | BK7: 1 | BQ7: 1 | BR7: 1 | BS7: 1 | BW7: 1
A8: =IFERROR(VLOOKUP(B8,Dienstgradstufen!$A$2:$D$19,3,0),0) -> 1 | B8: Anwerber | C8: Rapmar | D8: 45721 | E8: 45721 | F8: =IFERROR(VLOOKUP(B8,Dienstgradstufen!$A$2:$D$19,4,0),0) -> 0 | G8: =IF(AND(Dateneingabe!F8>0,Dateneingabe!F8<=Dateneingabe!H8),"Ja","") | H8: {=SUMPRODUCT(L8:DP8,($L$1:$DP$1-E8>=0)*1)} -> 15 | I8: {=IFERROR(H8/SUM(($L$1:$DP$1-E8>=0)*1),0)} -> 0.42857143 | J8: =SUM(L8:DP8) -> 15 | K8: {=IFERROR(J8/SUM(($L$1:$DP$1-D8>=0)*1),0)} -> 0.42857143 | BC8: 1 | BE8: 1 | BF8: 1 | BG8: 1 | BM8: 1 | BQ8: 1 | BT8: 1 | BW8: 1 | BY8: 1 | BZ8: 1 | CA8: 1 | CE8: 1 | CF8: 1 | CG8: 1 | CI8: 1
A9: =IFERROR(VLOOKUP(B9,Dienstgradstufen!$A$2:$D$19,3,0),0) -> 1 | B9: Anwerber | C9: Patler | D9: 45734 | E9: 45734 | F9: =IFERROR(VLOOKUP(B9,Dienstgradstufen!$A$2:$D$19,4,0),0) -> 0 | G9: =IF(AND(Dateneingabe!F9>0,Dateneingabe!F9<=Dateneingabe!H9),"Ja","") | H9: {=SUMPRODUCT(L9:DP9,($L$1:$DP$1-E9>=0)*1)} -> 7 | I9: {=IFERROR(H9/SUM(($L$1:$DP$1-E9>=0)*1),0)} -> 0.23333333 | J9: =SUM(L9:DP9) -> 7 | K9: {=IFERROR(J9/SUM(($L$1:$DP$1-D9>=0)*1),0)} -> 0.23333333 | BK9: 1 | BP9: 1 | BW9: 1 | BZ9: 1 | CA9: 1 | CG9: 1 | CH9: 1
A10: =IFERROR(VLOOKUP(B10,Dienstgradstufen!$A$2:$D$19,3,0),0) -> 1 | B10: Anwerber | C10: JMeister | D10: 45735 | E10: 45735 | F10: =IFERROR(VLOOKUP(B10,Dienstgradstufen!$A$2:$D$19,4,0),0) -> 0 | G10: =IF(AND(Dateneingabe!F10>0,Dateneingabe!F10<=Dateneingabe!H10),"Ja","") | H10: {=SUMPRODUCT(L10:DP10,($L$1:$DP$1-E10>=0)*1)} -> 3 | I10: {=IFERROR(H10/SUM(($L$1:$DP$1-E10>=0)*1),0)} -> 0.1 | J10: =SUM(L10:DP10) -> 3 | K10: {=IFERROR(J10/SUM(($L$1:$DP$1-D10>=0)*1),0)} -> 0.1 | BS10: 1 | BU10: 1 | CA10: 1
A11: =IFERROR(VLOOKUP(B11,Dienstgradstufen!$A$2:$D$19,3,0),0) -> 1 | B11: Anwerber | C11: Lucas | D11: 45755 | E11: 45755 | F11: =IFERROR(VLOOKUP(B11,Dienstgradstufen!$A$2:$D$19,4,0),0) -> 0 | G11: =IF(AND(Dateneingabe!F11>0,Dateneingabe!F11<=Dateneingabe!H11),"Ja","") | H11: {=SUMPRODUCT(L11:DP11,($L$1:$DP$1-E11>=0)*1)} -> 1 | I11: {=IFERROR(H11/SUM(($L$1:$DP$1-E11>=0)*1),0)} -> 0.045454545 | J11: =SUM(L11:DP11) -> 1 | K11: {=IFERROR(J11/SUM(($L$1:$DP$1-D11>=0)*1),0)} -> 0.045454545 | BQ11: 1
A12: =IFERROR(VLOOKUP(B12,Dienstgradstufen!$A$2:$D$19,3,0),0) -> 1 | B12: Anwerber | C12: Jonesy | D12: 45760 | E12: 45760 | F12: =IFERROR(VLOOKUP(B12,Dienstgradstufen!$A$2:$D$19,4,0),0) -> 0 | G12: =IF(AND(Dateneingabe!F12>0,Dateneingabe!F12<=Dateneingabe!H12),"Ja","") | H12: {=SUMPRODUCT(L12:DP12,($L$1:$DP$1-E12>=0)*1)} -> 5 | I12: {=IFERROR(H12/SUM(($L$1:$DP$1-E12>=0)*1),0)} -> 0.23809524 | J12: =SUM(L12:DP12) -> 5 | K12: {=IFERROR(J12/SUM(($L$1:$DP$1-D12>=0)*1),0)} -> 0.23809524 | BT12: 1 | BV12: 1 | BW12: 1 | CI12: 1 | CJ12: 1
A13: =IFERROR(VLOOKUP(B13,Dienstgradstufen!$A$2:$D$19,3,0),0) -> 1 | B13: Anwerber | C13: Schabo | D13: 45762 | E13: 45762 | F13: =IFERROR(VLOOKUP(B13,Dienstgradstufen!$A$2:$D$19,4,0),0) -> 0 | G13: =IF(AND(Dateneingabe!F13>0,Dateneingabe!F13<=Dateneingabe!H13),"Ja","") | H13: {=SUMPRODUCT(L13:DP13,($L$1:$DP$1-E13>=0)*1)} -> 12 | I13: {=IFERROR(H13/SUM(($L$1:$DP$1-E13>=0)*1),0)} -> 0.6 | J13: =SUM(L13:DP13) -> 12 | K13: {=IFERROR(J13/SUM(($L$1:$DP$1-D13>=0)*1),0)} -> 0.6 | BS13: 1 | BT13: 1 | BV13: 1 | BW13: 1 | BY13: 1 | BZ13: 1 | CB13: 1 | CC13: 1 | CG13: 1 | CI13: 1 | CJ13: 1 | CK13: 1
A14: =IFERROR(VLOOKUP(B14,Dienstgradstufen!$A$2:$D$19,3,0),0) -> 1 | B14: Anwerber | C14: Bismark | D14: 45767 | E14: 45767 | F14: =IFERROR(VLOOKUP(B14,Dienstgradstufen!$A$2:$D$19,4,0),0) -> 0 | G14: =IF(AND(Dateneingabe!F14>0,Dateneingabe!F14<=Dateneingabe!H14),"Ja","") | H14: {=SUMPRODUCT(L14:DP14,($L$1:$DP$1-E14>=0)*1)} -> 4 | I14: {=IFERROR(H14/SUM(($L$1:$DP$1-E14>=0)*1),0)} -> 0.22222222 | J14: =SUM(L14:DP14) -> 4 | K14: {=IFERROR(J14/SUM(($L$1:$DP$1-D14>=0)*1),0)} -> 0.22222222 | BW14: 1 | BY14: 1 | CB14: 1 | CC14: 1
A15: =IFERROR(VLOOKUP(B15,Dienstgradstufen!$A$2:$D$19,3,0),0) -> 1 | B15: Anwerber | C15: ZerOS | D15: 45771 | E15: 45771 | F15: =IFERROR(VLOOKUP(B15,Dienstgradstufen!$A$2:$D$19,4,0),0) -> 0 | G15: =IF(AND(Dateneingabe!F15>0,Dateneingabe!F15<=Dateneingabe!H15),"Ja","") | H15: {=SUMPRODUCT(L15:DP15,($L$1:$DP$1-E15>=0)*1)} -> 8 | I15: {=IFERROR(H15/SUM(($L$1:$DP$1-E15>=0)*1),0)} -> 0.47058824 | J15: =SUM(L15:DP15) -> 8 | K15: {=IFERROR(J15/SUM(($L$1:$DP$1-D15>=0)*1),0)} -> 0.47058824 | BV15: 1 | BZ15: 1 | CB15: 1 | CC15: 1 | CE15: 1 | CF15: 1 | CI15: 1 | CJ15: 1
A16: =IFERROR(VLOOKUP(B16,Dienstgradstufen!$A$2:$D$19,3,0),0) -> 1 | B16: Anwerber | C16: Dominus | D16: 45773 | E16: 45773 | F16: =IFERROR(VLOOKUP(B16,Dienstgradstufen!$A$2:$D$19,4,0),0) -> 0 | G16: =IF(AND(Dateneingabe!F16>0,Dateneingabe!F16<=Dateneingabe!H16),"Ja","") | H16: {=SUMPRODUCT(L16:DP16,($L$1:$DP$1-E16>=0)*1)} -> 0 | I16: {=IFERROR(H16/SUM(($L$1:$DP$1-E16>=0)*1),0)} -> 0 | J16: =SUM(L16:DP16) -> 0 | K16: {=IFERROR(J16/SUM(($L$1:$DP$1-D16>=0)*1),0)} -> 0
A17: =IFERROR(VLOOKUP(B17,Dienstgradstufen!$A$2:$D$19,3,0),0) -> 1 | B17: Anwerber | C17: Mecke | D17: 45778 | E17: 45778 | F17: =IFERROR(VLOOKUP(B17,Dienstgradstufen!$A$2:$D$19,4,0),0) -> 0 | G17: =IF(AND(Dateneingabe!F17>0,Dateneingabe!F17<=Dateneingabe!H17),"Ja","") | H17: {=SUMPRODUCT(L17:DP17,($L$1:$DP$1-E17>=0)*1)} -> 6 | I17: {=IFERROR(H17/SUM(($L$1:$DP$1-E17>=0)*1),0)} -> 0.4 | J17: =SUM(L17:DP17) -> 6 | K17: {=IFERROR(J17/SUM(($L$1:$DP$1-D17>=0)*1),0)} -> 0.4 | BW17: 1 | BY17: 1 | BZ17: 1 | CC17: 1 | CG17: 1 | CK17: 1
A18: =IFERROR(VLOOKUP(B18,Dienstgradstufen!$A$2:$D$19,3,0),0) -> 1 | B18: Anwerber | C18: CptIglo | D18: 45773 | E18: 45773 | F18: =IFERROR(VLOOKUP(B18,Dienstgradstufen!$A$2:$D$19,4,0),0) -> 0 | G18: =IF(AND(Dateneingabe!F18>0,Dateneingabe!F18<=Dateneingabe!H18),"Ja","") | H18: {=SUMPRODUCT(L18:DP18,($L$1:$DP$1-E18>=0)*1)} -> 3 | I18: {=IFERROR(H18/SUM(($L$1:$DP$1-E18>=0)*1),0)} -> 0.1875 | J18: =SUM(L18:DP18) -> 3 | K18: {=IFERROR(J18/SUM(($L$1:$DP$1-D18>=0)*1),0)} -> 0.1875 | BW18: 1 | BY18: 1 | CJ18: 1
A19: =IFERROR(VLOOKUP(B19,Dienstgradstufen!$A$2:$D$19,3,0),0) -> 1 | B19: Anwerber | C19: Dominus | D19: 45773 | E19: 45773 | F19: =IFERROR(VLOOKUP(B19,Dienstgradstufen!$A$2:$D$19,4,0),0) -> 0 | G19: =IF(AND(Dateneingabe!F19>0,Dateneingabe!F19<=Dateneingabe!H19),"Ja","") | H19: {=SUMPRODUCT(L19:DP19,($L$1:$DP$1-E19>=0)*1)} -> 0 | I19: {=IFERROR(H19/SUM(($L$1:$DP$1-E19>=0)*1),0)} -> 0 | J19: =SUM(L19:DP19) -> 0 | K19: {=IFERROR(J19/SUM(($L$1:$DP$1-D19>=0)*1),0)} -> 0
A20: =IFERROR(VLOOKUP(B20,Dienstgradstufen!$A$2:$D$19,3,0),0) -> 1 | B20: Anwerber | C20: Yeti | D20: 45771 | E20: 45771 | F20: =IFERROR(VLOOKUP(B20,Dienstgradstufen!$A$2:$D$19,4,0),0) -> 0 | G20: =IF(AND(Dateneingabe!F20>0,Dateneingabe!F20<=Dateneingabe!H20),"Ja","") | H20: {=SUMPRODUCT(L20:DP20,($L$1:$DP$1-E20>=0)*1)} -> 1 | I20: {=IFERROR(H20/SUM(($L$1:$DP$1-E20>=0)*1),0)} -> 0.058823529 | J20: =SUM(L20:DP20) -> 1 | K20: {=IFERROR(J20/SUM(($L$1:$DP$1-D20>=0)*1),0)} -> 0.058823529 | CC20: 1
A21: =IFERROR(VLOOKUP(B21,Dienstgradstufen!$A$2:$D$19,3,0),0) -> 1 | B21: Anwerber | C21: Mecke | D21: 45778 | E21: 45778 | F21: =IFERROR(VLOOKUP(B21,Dienstgradstufen!$A$2:$D$19,4,0),0) -> 0 | G21: =IF(AND(Dateneingabe!F21>0,Dateneingabe!F21<=Dateneingabe!H21),"Ja","") | H21: {=SUMPRODUCT(L21:DP21,($L$1:$DP$1-E21>=0)*1)} -> 3 | I21: {=IFERROR(H21/SUM(($L$1:$DP$1-E21>=0)*1),0)} -> 0.2 | J21: =SUM(L21:DP21) -> 3 | K21: {=IFERROR(J21/SUM(($L$1:$DP$1-D21>=0)*1),0)} -> 0.2 | CD21: 1 | CE21: 1 | CJ21: 1
A22: =IFERROR(VLOOKUP(B22,Dienstgradstufen!$A$2:$D$19,3,0),0) -> 1 | B22: Anwerber | C22: Brandt | D22: 45791 | E22: 45791 | F22: =IFERROR(VLOOKUP(B22,Dienstgradstufen!$A$2:$D$19,4,0),0) -> 0 | G22: =IF(AND(Dateneingabe!F22>0,Dateneingabe!F22<=Dateneingabe!H22),"Ja","") | H22: {=SUMPRODUCT(L22:DP22,($L$1:$DP$1-E22>=0)*1)} -> 7 | I22: {=IFERROR(H22/SUM(($L$1:$DP$1-E22>=0)*1),0)} -> 0.77777778 | J22: =SUM(L22:DP22) -> 7 | K22: {=IFERROR(J22/SUM(($L$1:$DP$1-D22>=0)*1),0)} -> 0.77777778 | CC22: 1 | CE22: 1 | CF22: 1 | CG22: 1 | CI22: 1 | CJ22: 1 | CK22: 1
A23: =IFERROR(VLOOKUP(B23,Dienstgradstufen!$A$2:$D$19,3,0),0) -> 1 | B23: Anwerber | C23: Snowy | D23: 45796 | E23: 45796 | F23: =IFERROR(VLOOKUP(B23,Dienstgradstufen!$A$2:$D$19,4,0),0) -> 0 | G23: =IF(AND(Dateneingabe!F23>0,Dateneingabe!F23<=Dateneingabe!H23),"Ja","") | H23: {=SUMPRODUCT(L23:DP23,($L$1:$DP$1-E23>=0)*1)} -> 4 | I23: {=IFERROR(H23/SUM(($L$1:$DP$1-E23>=0)*1),0)} -> 0.57142857 | J23: =SUM(L23:DP23) -> 4 | K23: {=IFERROR(J23/SUM(($L$1:$DP$1-D23>=0)*1),0)} -> 0.57142857 | CE23: 1 | CG23: 1 | CI23: 1 | CK23: 1
A24: =IFERROR(VLOOKUP(B24,Dienstgradstufen!$A$2:$D$19,3,0),0) -> 1 | B24: Anwerber | C24: Herbert | D24: 45799 | E24: 45799 | F24: =IFERROR(VLOOKUP(B24,Dienstgradstufen!$A$2:$D$19,4,0),0) -> 0 | G24: =IF(AND(Dateneingabe!F24>0,Dateneingabe!F24<=Dateneingabe!H24),"Ja","") | H24: {=SUMPRODUCT(L24:DP24,($L$1:$DP$1-E24>=0)*1)} -> 0 | I24: {=IFERROR(H24/SUM(($L$1:$DP$1-E24>=0)*1),0)} -> 0 | J24: =SUM(L24:DP24) -> 0 | K24: {=IFERROR(J24/SUM(($L$1:$DP$1-D24>=0)*1),0)} -> 0
A25: =IFERROR(VLOOKUP(B25,Dienstgradstufen!$A$2:$D$19,3,0),0) -> 1 | B25: Anwerber | C25: Lutz | D25: 45807 | E25: 45807 | F25: =IFERROR(VLOOKUP(B25,Dienstgradstufen!$A$2:$D$19,4,0),0) -> 0 | G25: =IF(AND(Dateneingabe!F25>0,Dateneingabe!F25<=Dateneingabe!H25),"Ja","") | H25: {=SUMPRODUCT(L25:DP25,($L$1:$DP$1-E25>=0)*1)} -> 1 | I25: {=IFERROR(H25/SUM(($L$1:$DP$1-E25>=0)*1),0)} -> 1 | J25: =SUM(L25:DP25) -> 1 | K25: {=IFERROR(J25/SUM(($L$1:$DP$1-D25>=0)*1),0)} -> 1 | CK25: 1
A26: =IFERROR(VLOOKUP(B26,Dienstgradstufen!$A$2:$D$19,3,0),0) -> 1 | B26: Anwerber | C26: Vorlage | D26: 45773 | E26: 45773 | F26: =IFERROR(VLOOKUP(B26,Dienstgradstufen!$A$2:$D$19,4,0),0) -> 0 | G26: =IF(AND(Dateneingabe!F26>0,Dateneingabe!F26<=Dateneingabe!H26),"Ja","") | H26: {=SUMPRODUCT(L26:DP26,($L$1:$DP$1-E26>=0)*1)} -> 0 | I26: {=IFERROR(H26/SUM(($L$1:$DP$1-E26>=0)*1),0)} -> 0 | J26: =SUM(L26:DP26) -> 0 | K26: {=IFERROR(J26/SUM(($L$1:$DP$1-D26>=0)*1),0)} -> 0
A27: =IFERROR(VLOOKUP(B27,Dienstgradstufen!$A$2:$D$19,3,0),0) -> 1 | B27: Anwerber | C27: Vorlage | D27: 45773 | E27: 45773 | F27: =IFERROR(VLOOKUP(B27,Dienstgradstufen!$A$2:$D$19,4,0),0) -> 0 | G27: =IF(AND(Dateneingabe!F27>0,Dateneingabe!F27<=Dateneingabe!H27),"Ja","") | H27: {=SUMPRODUCT(L27:DP27,($L$1:$DP$1-E27>=0)*1)} -> 0 | I27: {=IFERROR(H27/SUM(($L$1:$DP$1-E27>=0)*1),0)} -> 0 | J27: =SUM(L27:DP27) -> 0 | K27: {=IFERROR(J27/SUM(($L$1:$DP$1-D27>=0)*1),0)} -> 0
A28: =IFERROR(VLOOKUP(B28,Dienstgradstufen!$A$2:$D$19,3,0),0) -> 1 | B28: Anwerber | C28: Vorlage | D28: 45773 | E28: 45773 | F28: =IFERROR(VLOOKUP(B28,Dienstgradstufen!$A$2:$D$19,4,0),0) -> 0 | G28: =IF(AND(Dateneingabe!F28>0,Dateneingabe!F28<=Dateneingabe!H28),"Ja","") | H28: {=SUMPRODUCT(L28:DP28,($L$1:$DP$1-E28>=0)*1)} -> 0 | I28: {=IFERROR(H28/SUM(($L$1:$DP$1-E28>=0)*1),0)} -> 0 | J28: =SUM(L28:DP28) -> 0 | K28: {=IFERROR(J28/SUM(($L$1:$DP$1-D28>=0)*1),0)} -> 0

Sheet Dienstgradstufen
A1: Dienstgrad | C1: Dienstgradstufe | D1: Beförderungsschwelle
A2: Anwerber | B2: Anwerber | C2: 1
A3: Panzergrenadier-AW | B3: Anwerber | C3: 1
A4: Panzergrenadier | B4: Mannschaft | C4: 2 | D4: 8
A5: Obergrenadier | B5: Mannschaft | C5: 3 | D5: 10
A6: Gefreiter | B6: Mannschaft | C6: 4 | D6: 12
A7: Obergefreiter | B7: Mannschaft | C7: 5 | D7: 16
A8: Stabsgefreiter | B8: Mannschaft | C8: 6
A9: Unteroffizier | B9: Mannschaft | C9: 7
A10: Unterfeldwebel | B10: Unteroffizier | C10: 8
A11: Feldwebel | B11: Unteroffizier | C11: 9
A12: Oberfeldwebel | B12: Unteroffizier | C12: 10
A13: Stabsfeldwebel | B13: Unteroffizier | C13: 11
A14: Leutnant | B14: Offizier | C14: 12
A15: Oberleutnant | B15: Offizier | C15: 13
A16: Hauptmann | B16: Offizier | C16: 14
A17: Major | B17: Offizier | C17: 15
A18: Oberstleutnant | B18: Führungsoffizier | C18: 16
A19: Oberst | B19: Führungsoffizier | C19: 17
B22: geführte Gefechte als Offizier
B23: geführte Gefechte als Kommandant
B24: angemeldet aber nicht erschienen

Sheet Tabelle1
B2: Anwerber | C2: Spalte1 | D2: AW Zeit Ende | E2: GA abgeschlossen | F2: Aktivität
B3: Anwerber | C3: Jemand | D3: 45699 | E3: Nein | F3: 0.28
B4: Anwerber | C4: Achi | D4: 45716 | E4: Nein | F4: 0.33
B5: Anwerber | C5: Li (Rieger) | D5: 45723 | E5: Nein | F5: 0.37
B6: Anwerber | C6: Thor | D6: 45737 | E6: Nein | F6: 0.9
B7: Anwerber | C7: Ares | D7: 45749 | E7: Nein | F7: 0.14
B8: Anwerber | C8: Hahnus | D8: 45750 | E8: Nein | F8: 0.83
B9: Anwerber | C9: RuhigerMC | D9: 45756 | E9: Nein | F9: 0.4
B10: Anwerber | C10: Kesch | D10: 45755 | E10: Nein | F10: 0.6
B11: Anwerber | C11: Abfall | D11: 45756 | E11: Nein | F11: 0.6
B12: Anwerber | C12: Thorsson | D12: 45757 | E12: Nein | F12: 1
B13: Anwerber | C13: Boo | D13: 45757 | E13: Nein | F13: 0.75
B14: Anwerber | C14: Benedetto | D14: 45755 | E14: Nein | F14: 0.4
... B63: Anwerber | C63: Marc | D63: 45794 | E63: Nein | F63: 25
